Workbook

Sheet Summary
A1: Sponsor pipeline v2: follow the money
A2: Built 24 Oct 2026. Tier A = proven spend on our audience; B = serves our audience; C = large/generic (parked).
B4: Companies | C4: Expected value (€) | D4: Won (€)
A5: Tier A | B5: =COUNTIF('Pipeline A-B'!$E$2:$E$132,"A") | C5: =SUMIF('Pipeline A-B'!$E$2:$E$132,"A",'Pipeline A-B'!$P$2:$P$132) | D5: =SUMIFS('Pipeline A-B'!$N$2:$N$132,'Pipeline A-B'!$E$2:$E$132,"A",'Pipeline A-B'!$R$2:$R$132,"Won")
A6: Tier B | B6: =COUNTIF('Pipeline A-B'!$E$2:$E$132,"B") | C6: =SUMIF('Pipeline A-B'!$E$2:$E$132,"B",'Pipeline A-B'!$P$2:$P$132) | D6: =SUMIFS('Pipeline A-B'!$N$2:$N$132,'Pipeline A-B'!$E$2:$E$132,"B",'Pipeline A-B'!$R$2:$R$132,"Won")
A7: Tier C (parked) | B7: =COUNTA('Later (tier C)'!$A$2:$A$70) | C7: =SUM('Later (tier C)'!$P$2:$P$70) | D7: =SUMIF('Later (tier C)'!$R$2:$R$70,"Won",'Later (tier C)'!$N$2:$N$70)
A8: Total | B8: =SUM(B5:B7) | C8: =SUM(C5:C7) | D8: =SUM(D5:D7)
A9: Share of tier A + B | B9: =(B5+B6)/B8
A11: Edition | B11: A + B companies | C11: Expected value (€)
A12: LU | B12: =SUMPRODUCT(--ISNUMBER(SEARCH("LU",'Pipeline A-B'!$D$2:$D$132))) | C12: =SUMPRODUCT(ISNUMBER(SEARCH("LU",'Pipeline A-B'!$D$2:$D$132))*'Pipeline A-B'!$P$2:$P$132)
A13: FR | B13: =SUMPRODUCT(--ISNUMBER(SEARCH("FR",'Pipeline A-B'!$D$2:$D$132))) | C13: =SUMPRODUCT(ISNUMBER(SEARCH("FR",'Pipeline A-B'!$D$2:$D$132))*'Pipeline A-B'!$P$2:$P$132)
A14: CH | B14: =SUMPRODUCT(--ISNUMBER(SEARCH("CH",'Pipeline A-B'!$D$2:$D$132))) | C14: =SUMPRODUCT(ISNUMBER(SEARCH("CH",'Pipeline A-B'!$D$2:$D$132))*'Pipeline A-B'!$P$2:$P$132)
A15: BR | B15: =SUMPRODUCT(--ISNUMBER(SEARCH("BR",'Pipeline A-B'!$D$2:$D$132))) | C15: =SUMPRODUCT(ISNUMBER(SEARCH("BR",'Pipeline A-B'!$D$2:$D$132))*'Pipeline A-B'!$P$2:$P$132)
A16: US | B16: =SUMPRODUCT(--ISNUMBER(SEARCH("US",'Pipeline A-B'!$D$2:$D$132))) | C16: =SUMPRODUCT(ISNUMBER(SEARCH("US",'Pipeline A-B'!$D$2:$D$132))*'Pipeline A-B'!$P$2:$P$132)
A17: IL | B17: =SUMPRODUCT(--ISNUMBER(SEARCH("IL",'Pipeline A-B'!$D$2:$D$132))) | C17: =SUMPRODUCT(ISNUMBER(SEARCH("IL",'Pipeline A-B'!$D$2:$D$132))*'Pipeline A-B'!$P$2:$P$132)
A18: A company with several editions counts in each, so edition rows add up to more than the total.
A20: Status | B20: A + B companies
A21: To contact | B21: =COUNTIF('Pipeline A-B'!$R$2:$R$132,"To contact")
A22: Contacted | B22: =COUNTIF('Pipeline A-B'!$R$2:$R$132,"Contacted")
A23: Replied | B23: =COUNTIF('Pipeline A-B'!$R$2:$R$132,"Replied")
A24: Call booked | B24: =COUNTIF('Pipeline A-B'!$R$2:$R$132,"Call booked")
A25: Proposal sent | B25: =COUNTIF('Pipeline A-B'!$R$2:$R$132,"Proposal sent")
A26: Won | B26: =COUNTIF('Pipeline A-B'!$R$2:$R$132,"Won")
A27: Lost | B27: =COUNTIF('Pipeline A-B'!$R$2:$R$132,"Lost")

Sheet Pipeline A-B
A1: ID | B1: Company | C1: Sector | D1: Editions | E1: Tier | F1: Size | G1: Evidence URL | H1: Evidence | I1: Evidence year | J1: Evidence check | K1: Who to reach | L1: Channel | M1: Offer | N1: Deal value year 1 (€) | O1: Close probability | P1: Expected value (€) | Q1: Priority score | R1: Status | S1: Next action | T1: Next action date | U1: Owner | V1: Capital origin
A2: S179 | B2: Cross Border Wealth | C2: Cross-border wealth adviser (private) | D2: US | E2: A | F2: S | G2: https://expressoemprego.pt/emprego/international-investment-advisor-financial-advisor/2428178 | H2: Wealth Partner tier (D33): Preparing a Lisbon office for US-connected individuals abroad (job ad, May 2026) (prompt 15) | I2: 2026 | J2: Search result | K2: Head of international or Portugal desk | L2: LinkedIn (named role), then company email | M2: Wealth Partner | N2: =INDEX(Settings!$B$4:$B$15,MATCH(M2,Settings!$A$4:$A$15,0)) | O2: =IF(E2="A",IF(I2>=2022,Settings!$B$18,Settings!$B$19),IF(E2="B",Settings!$B$20,Settings!$B$21))+IF(F2="S",Settings!$B$22,0) | P2: =N2*O2 | Q2: =P2*INDEX(Settings!$B$25:$B$27,MATCH(F2,Settings!$A$25:$A$27,0)) | R2: To contact | S2: Touch 1 (sponsors/outreach/v3) | T2: 2026-11-09 | U2: Partner | V2: United States
A3: S180 | B3: Euro American Financial Advisors | C3: Cross-border wealth adviser (private) | D3: US | E3: A | F3: S | G3: https://www.expatfocus.com/?p=51322 | H3: Wealth Partner tier (D33): Panel on moving to Portugal at the 2026 US Expats Financial Conference (prompt 15) | I3: 2026 | J3: Search result | K3: Head of international or Portugal desk | L3: LinkedIn (named role), then company email | M3: Wealth Partner | N3: =INDEX(Settings!$B$4:$B$15,MATCH(M3,Settings!$A$4:$A$15,0)) | O3: =IF(E3="A",IF(I3>=2022,Settings!$B$18,Settings!$B$19),IF(E3="B",Settings!$B$20,Settings!$B$21))+IF(F3="S",Settings!$B$22,0) | P3: =N3*O3 | Q3: =P3*INDEX(Settings!$B$25:$B$27,MATCH(F3,Settings!$A$25:$A$27,0)) | R3: To contact | S3: Touch 1 (sponsors/outreach/v3) | T3: 2026-11-09 | U3: Partner | V3: United States
A4: S181 | B4: Finalib | C4: Wealth adviser (private) | D4: FR | E4: A | F4: S | G4: https://finalib.fr/blog/fiscalite/expatriation-fiscale-2026-quitter-france-impots | H4: Wealth Partner tier (D33): Content on tax expatriation from France to Portugal (2026) (prompt 15) | I4: 2026 | J4: Search result | K4: Head of international or Portugal desk | L4: LinkedIn (named role), then company email | M4: Wealth Partner | N4: =INDEX(Settings!$B$4:$B$15,MATCH(M4,Settings!$A$4:$A$15,0)) | O4: =IF(E4="A",IF(I4>=2022,Settings!$B$18,Settings!$B$19),IF(E4="B",Settings!$B$20,Settings!$B$21))+IF(F4="S",Settings!$B$22,0) | P4: =N4*O4 | Q4: =P4*INDEX(Settings!$B$25:$B$27,MATCH(F4,Settings!$A$25:$A$27,0)) | R4: To contact | S4: Touch 1 (sponsors/outreach/v3) | T4: 2026-11-09 | U4: Partner | V4: France
A5: S182 | B5: Green Ocean Global Advisors | C5: Cross-border wealth adviser (private) | D5: US | E5: A | F5: S | G5: https://podcastaddict.com/episode/https%3A%2F%2Fwww.podtrac.com%2Fpts%2Fredirect.mp3%2Ftraffic.megaphone.fm%2FTPGL5408537107.mp3&podcastId=6068358 | H5: Wealth Partner tier (D33): Lisbon-based cross-border planning for Americans in Portugal (podcast, June 2026) (prompt 15) | I5: 2026 | J5: Search result | K5: Head of international or Portugal desk | L5: LinkedIn (named role), then company email | M5: Wealth Partner | N5: =INDEX(Settings!$B$4:$B$15,MATCH(M5,Settings!$A$4:$A$15,0)) | O5: =IF(E5="A",IF(I5>=2022,Settings!$B$18,Settings!$B$19),IF(E5="B",Settings!$B$20,Settings!$B$21))+IF(F5="S",Settings!$B$22,0) | P5: =N5*O5 | Q5: =P5*INDEX(Settings!$B$25:$B$27,MATCH(F5,Settings!$A$25:$A$27,0)) | R5: To contact | S5: Touch 1 (sponsors/outreach/v3) | T5: 2026-11-09 | U5: Partner | V5: United States
A6: S183 | B6: Liberty Atlantic Advisors | C6: Cross-border wealth adviser (private) | D6: US | E6: A | F6: S | G6: https://www.kiplinger.com/author/ricardo-jesus-mba | H6: Wealth Partner tier (D33): Fiduciary residency and international tax planning for Americans in Portugal (prompt 15) | I6: 2026 | J6: Search result | K6: Head of international or Portugal desk | L6: LinkedIn (named role), then company email | M6: Wealth Partner | N6: =INDEX(Settings!$B$4:$B$15,MATCH(M6,Settings!$A$4:$A$15,0)) | O6: =IF(E6="A",IF(I6>=2022,Settings!$B$18,Settings!$B$19),IF(E6="B",Settings!$B$20,Settings!$B$21))+IF(F6="S",Settings!$B$22,0) | P6: =N6*O6 | Q6: =P6*INDEX(Settings!$B$25:$B$27,MATCH(F6,Settings!$A$25:$A$27,0)) | R6: To contact | S6: Touch 1 (sponsors/outreach/v3) | T6: 2026-11-09 | U6: Partner | V6: United States
A7: S184 | B7: Lisbon Family Office | C7: Family office (private) | D7: LU, FR, CH, BR, US, IL | E7: A | F7: S | G7: https://altss.com/profile/lisbon-family-office | H7: Wealth Partner tier (D33): CMVM-regulated multi-family office; existing MFOs mainly target non-resident clients (prompt 15) | I7: 2025 | J7: Search result | K7: Head of international or Portugal desk | L7: LinkedIn (named role), then company email | M7: Wealth Partner | N7: =INDEX(Settings!$B$4:$B$15,MATCH(M7,Settings!$A$4:$A$15,0)) | O7: =IF(E7="A",IF(I7>=2022,Settings!$B$18,Settings!$B$19),IF(E7="B",Settings!$B$20,Settings!$B$21))+IF(F7="S",Settings!$B$22,0) | P7: =N7*O7 | Q7: =P7*INDEX(Settings!$B$25:$B$27,MATCH(F7,Settings!$A$25:$A$27,0)) | R7: To contact | S7: Touch 1 (sponsors/outreach/v3) | T7: 2026-11-09 | U7: Partner | V7: Portugal
A8: S185 | B8: Neofa | C8: International tax adviser (private) | D8: FR | E8: A | F8: S | G8: https://neofa.com/fr/fiscalite/fiscalite-des-particuliers/conseil-fiscalite-internationale/exit-tax-france/ | H8: Wealth Partner tier (D33): French international tax firm; guides on leaving France for Spain and Portugal (prompt 15) | I8: 2026 | J8: Search result | K8: Partner, private clients | L8: LinkedIn (named role), then company email | M8: Wealth Partner | N8: =INDEX(Settings!$B$4:$B$15,MATCH(M8,Settings!$A$4:$A$15,0)) | O8: =IF(E8="A",IF(I8>=2022,Settings!$B$18,Settings!$B$19),IF(E8="B",Settings!$B$20,Settings!$B$21))+IF(F8="S",Settings!$B$22,0) | P8: =N8*O8 | Q8: =P8*INDEX(Settings!$B$25:$B$27,MATCH(F8,Settings!$A$25:$A$27,0)) | R8: To contact | S8: Touch 1 (sponsors/outreach/v3) | T8: 2026-11-09 | U8: Partner | V8: France
A9: S170 | B9: Millennium bcp Private Banking | C9: Private banking / wealth / private client | D9: LU, FR, CH, BR, US, IL | E9: A | F9: L | G9: https://chambers.com/department/millennium-bcp-private-banks-high-net-worth-21:2699:174:1:249515 | H9: Ranked by Chambers in private banking (High Net Worth). | I9: 2026 | J9: Search result, not opened | K9: Head of private clients / Portugal desk | L9: Website: millenniumbcp.pt | M9: Wealth Partner | N9: =INDEX(Settings!$B$4:$B$15,MATCH(M9,Settings!$A$4:$A$15,0)) | O9: =IF(E9="A",IF(I9>=2022,Settings!$B$18,Settings!$B$19),IF(E9="B",Settings!$B$20,Settings!$B$21))+IF(F9="S",Settings!$B$22,0) | P9: =N9*O9 | Q9: =P9*INDEX(Settings!$B$25:$B$27,MATCH(F9,Settings!$A$25:$A$27,0)) | R9: Not contacted | S9: Approach with brochure (D40) | U9: Partner | V9: not assessed
A10: S186 | B10: Banco ATLANTICO Europa | C10: Bank (private) | D10: LU, FR, CH, BR, US, IL | E10: A | F10: M | G10: https://www.portugalresident.com/the-bank-for-people-of-the-world-in-portugal/ | H10: Wealth Partner tier (D33): Paid sponsored text in Portugal Resident aimed at non-residents: proven spend on an international audience (prompt 15) | I10: 2025 | J10: Search result | K10: Head of international or Portugal desk | L10: LinkedIn (named role), then company email | M10: Wealth Partner | N10: =INDEX(Settings!$B$4:$B$15,MATCH(M10,Settings!$A$4:$A$15,0)) | O10: =IF(E10="A",IF(I10>=2022,Settings!$B$18,Settings!$B$19),IF(E10="B",Settings!$B$20,Settings!$B$21))+IF(F10="S",Settings!$B$22,0) | P10: =N10*O10 | Q10: =P10*INDEX(Settings!$B$25:$B$27,MATCH(F10,Settings!$A$25:$A$27,0)) | R10: To contact | S10: Touch 1 (sponsors/outreach/v3) | T10: 2026-11-09 | U10: Partner | V10: Angola
A11: S187 | B11: Blacktower Financial Management | C11: Cross-border wealth adviser (private) | D11: US | E11: A | F11: M | G11: https://international-adviser.com/blacktower-unveils-portugal-expat-service-for-us-nationals/ | H11: Wealth Partner tier (D33): American desk for US nationals relocating to Portugal (prompt 15) | I11: 2022 | J11: Search result | K11: Head of international or Portugal desk | L11: LinkedIn (named role), then company email | M11: Wealth Partner | N11: =INDEX(Settings!$B$4:$B$15,MATCH(M11,Settings!$A$4:$A$15,0)) | O11: =IF(E11="A",IF(I11>=2022,Settings!$B$18,Settings!$B$19),IF(E11="B",Settings!$B$20,Settings!$B$21))+IF(F11="S",Settings!$B$22,0) | P11: =N11*O11 | Q11: =P11*INDEX(Settings!$B$25:$B$27,MATCH(F11,Settings!$A$25:$A$27,0)) | R11: To contact | S11: Touch 1 (sponsors/outreach/v3) | T11: 2026-11-09 | U11: Partner | V11: Gibraltar / UK
A12: S188 | B12: Dixcart (Portugal) | C12: Corporate and family-office services (private) | D12: LU, FR, CH, US, IL | E12: A | F12: M | G12: https://www.dixcart.com/es/?p=612 | H12: Wealth Partner tier (D33): Family office and relocation services in Portugal for international families (prompt 15) | I12: 2025 | J12: Search result | K12: Head of international or Portugal desk | L12: LinkedIn (named role), then company email | M12: Wealth Partner | N12: =INDEX(Settings!$B$4:$B$15,MATCH(M12,Settings!$A$4:$A$15,0)) | O12: =IF(E12="A",IF(I12>=2022,Settings!$B$18,Settings!$B$19),IF(E12="B",Settings!$B$20,Settings!$B$21))+IF(F12="S",Settings!$B$22,0) | P12: =N12*O12 | Q12: =P12*INDEX(Settings!$B$25:$B$27,MATCH(F12,Settings!$A$25:$A$27,0)) | R12: To contact | S12: Touch 1 (sponsors/outreach/v3) | T12: 2026-11-09 | U12: Partner | V12: United Kingdom
A13: S189 | B13: Ombria Algarve (Viceroy Residences) | C13: Prime developer (private) | D13: FR, LU, CH, US | E13: A | F13: M | G13: https://www.portugalresident.com/80-of-viceroy-residents-already-sold-at-ombria/ | H13: Wealth Partner tier (D33): Algarve resort; buyers British, Dutch, Portuguese, French and American (prompt 15) | I13: 2024 | J13: Search result | K13: Sales or marketing director | L13: LinkedIn (named role), then company email | M13: Wealth Partner | N13: =INDEX(Settings!$B$4:$B$15,MATCH(M13,Settings!$A$4:$A$15,0)) | O13: =IF(E13="A",IF(I13>=2022,Settings!$B$18,Settings!$B$19),IF(E13="B",Settings!$B$20,Settings!$B$21))+IF(F13="S",Settings!$B$22,0) | P13: =N13*O13 | Q13: =P13*INDEX(Settings!$B$25:$B$27,MATCH(F13,Settings!$A$25:$A$27,0)) | R13: To contact | S13: Touch 1 (sponsors/outreach/v3) | T13: 2026-11-09 | U13: Partner | V13: Finland
A14: S190 | B14: Overseas (Karl Lagerfeld Residences Lisbon) | C14: Prime developer (private) | D14: FR, BR, US, LU, CH | E14: A | F14: M | G14: https://econews.pt/2026/06/04/karl-lagerfeld-residences-launches-sales-in-10-markets/ | H14: Wealth Partner tier (D33): Branded residences in Lisbon marketed in 10 markets incl. France, the US and Brazil (June 2026) (prompt 15) | I14: 2026 | J14: Search result | K14: Sales or marketing director | L14: LinkedIn (named role), then company email | M14: Wealth Partner | N14: =INDEX(Settings!$B$4:$B$15,MATCH(M14,Settings!$A$4:$A$15,0)) | O14: =IF(E14="A",IF(I14>=2022,Settings!$B$18,Settings!$B$19),IF(E14="B",Settings!$B$20,Settings!$B$21))+IF(F14="S",Settings!$B$22,0) | P14: =N14*O14 | Q14: =P14*INDEX(Settings!$B$25:$B$27,MATCH(F14,Settings!$A$25:$A$27,0)) | R14: To contact | S14: Touch 1 (sponsors/outreach/v3) | T14: 2026-11-09 | U14: Partner | V14: Portugal
A15: S191 | B15: Rivage Properties (The View II) | C15: Prime developer (private) | D15: LU, FR, CH | E15: A | F15: M | G15: https://www.essential-business.pt/2024/06/14/rivage-invests-e20-million-in-homes-near-porto/ | H15: Wealth Partner tier (D33): Apartments by the Douro from 755,000 € to 1.5 M€ near Porto (prompt 15) | I15: 2024 | J15: Search result | K15: Sales or marketing director | L15: LinkedIn (named role), then company email | M15: Wealth Partner | N15: =INDEX(Settings!$B$4:$B$15,MATCH(M15,Settings!$A$4:$A$15,0)) | O15: =IF(E15="A",IF(I15>=2022,Settings!$B$18,Settings!$B$19),IF(E15="B",Settings!$B$20,Settings!$B$21))+IF(F15="S",Settings!$B$22,0) | P15: =N15*O15 | Q15: =P15*INDEX(Settings!$B$25:$B$27,MATCH(F15,Settings!$A$25:$A$27,0)) | R15: To contact | S15: Touch 1 (sponsors/outreach/v3) | T15: 2026-11-09 | U15: Partner | V15: Portugal
A16: S192 | B16: Sable International | C16: Cross-border wealth adviser (private) | D16: US | E16: A | F16: M | G16: https://www.sableinternational.com/blog/living-in-portugal--is-your-wealth-plan-keeping-up | H16: Wealth Partner tier (D33): Consultation campaign for people in Portugal with US, UK or South African ties (Nov 2026) (prompt 15) | I16: 2026 | J16: Search result | K16: Head of international or Portugal desk | L16: LinkedIn (named role), then company email | M16: Wealth Partner | N16: =INDEX(Settings!$B$4:$B$15,MATCH(M16,Settings!$A$4:$A$15,0)) | O16: =IF(E16="A",IF(I16>=2022,Settings!$B$18,Settings!$B$19),IF(E16="B",Settings!$B$20,Settings!$B$21))+IF(F16="S",Settings!$B$22,0) | P16: =N16*O16 | Q16: =P16*INDEX(Settings!$B$25:$B$27,MATCH(F16,Settings!$A$25:$A$27,0)) | R16: To contact | S16: Touch 1 (sponsors/outreach/v3) | T16: 2026-11-09 | U16: Partner | V16: United Kingdom
A17: S193 | B17: Sovereign Group (Portugal) | C17: Corporate and tax services (private) | D17: LU, FR, CH, US, IL | E17: A | F17: M | G17: https://www.sovereigngroup.com/news/the-ifici-a-sharper-edge-for-attracting-global-talent-to-portugal/ | H17: Wealth Partner tier (D33): Publishes IFICI guidance for people relocating to Portugal (prompt 15) | I17: 2025 | J17: Search result | K17: Partner, private clients | L17: LinkedIn (named role), then company email | M17: Wealth Partner | N17: =INDEX(Settings!$B$4:$B$15,MATCH(M17,Settings!$A$4:$A$15,0)) | O17: =IF(E17="A",IF(I17>=2022,Settings!$B$18,Settings!$B$19),IF(E17="B",Settings!$B$20,Settings!$B$21))+IF(F17="S",Settings!$B$22,0) | P17: =N17*O17 | Q17: =P17*INDEX(Settings!$B$25:$B$27,MATCH(F17,Settings!$A$25:$A$27,0)) | R17: To contact | S17: Touch 1 (sponsors/outreach/v3) | T17: 2026-11-09 | U17: Partner | V17: Gibraltar
A18: S157 | B18: Ando Living | C18: Developer (Comporta) | D18: LU, FR, CH, BR, US, IL | E18: A | F18: L | G18: https://www.idealista.pt/en/news/node/71011 | H18: First Comporta project: 16 luxury villas for international buyers. | I18: 2026 | J18: Search result, not opened | K18: Fundadores / vendas | L18: Website contact / LinkedIn | M18: Area placement (Prime) | N18: =INDEX(Settings!$B$4:$B$15,MATCH(M18,Settings!$A$4:$A$15,0)) | O18: =IF(E18="A",IF(I18>=2022,Settings!$B$18,Settings!$B$19),IF(E18="B",Settings!$B$20,Settings!$B$21))+IF(F18="S",Settings!$B$22,0) | P18: =N18*O18 | Q18: =P18*INDEX(Settings!$B$25:$B$27,MATCH(F18,Settings!$A$25:$A$27,0)) | R18: Not contacted | S18: Approach with brochure (D40) | U18: Partner | V18: not assessed
A19: S156 | B19: Herdade da Comporta | C19: Developer (Comporta) | D19: LU, FR, CH, BR, US, IL | E19: A | F19: L | G19: https://www.idealista.pt/en/news/node/61843 | H19: The estate bought by the Amorim family and partners; selling land for luxury tourism and residential projects. | I19: 2026 | J19: Search result, not opened | K19: Administração / desenvolvimento | L19: Website: herdadedacomporta.pt | M19: Area placement (Prime) | N19: =INDEX(Settings!$B$4:$B$15,MATCH(M19,Settings!$A$4:$A$15,0)) | O19: =IF(E19="A",IF(I19>=2022,Settings!$B$18,Settings!$B$19),IF(E19="B",Settings!$B$20,Settings!$B$21))+IF(F19="S",Settings!$B$22,0) | P19: =N19*O19 | Q19: =P19*INDEX(Settings!$B$25:$B$27,MATCH(F19,Settings!$A$25:$A$27,0)) | R19: Not contacted | S19: Approach with brochure (D40) | U19: Partner | V19: not assessed
A20: S178 | B20: OneMark Properties | C20: Developer (Lisbon, Grândola, Sines; Porto and Algarve planned) | D20: LU, FR, CH, BR, US, IL | E20: A | F20: L | G20: https://www.idealista.pt/news/node/75369 | H20: Founded early 2026 by José Cardoso Botelho (ex-Vanguard CEO); 7 projects in study (ultraluxury, luxury, premium, flex living, mid); initial 100 M€; targets high-net-worth buyers incl. Gulf investors. Pre-launch: ideal Founding Partner | I20: 2026 | J20: Opened | K20: Founder / CEO | L20: Website: to confirm | M20: Area placement (Prime) + launch | N20: =INDEX(Settings!$B$4:$B$15,MATCH(M20,Settings!$A$4:$A$15,0)) | O20: =IF(E20="A",IF(I20>=2022,Settings!$B$18,Settings!$B$19),IF(E20="B",Settings!$B$20,Settings!$B$21))+IF(F20="S",Settings!$B$22,0) | P20: =N20*O20 | Q20: =P20*INDEX(Settings!$B$25:$B$27,MATCH(F20,Settings!$A$25:$A$27,0)) | R20: Not contacted | S20: Private demo (prompt 26) then approach | U20: Partner | V20: not assessed
A21: S159 | B21: Vale do Lobo | C21: Developer (Algarve · Triângulo Dourado) | D21: LU, FR, CH, BR, US, IL | E21: A | F21: L | G21: https://www.idealista.pt/en/news/luxury-real-estate-in-portugal/2025/02/06/67912-vale-do-lobo-in-the-algarve-invests-over-eu200-million-in-luxury-homes | H21: Investing over 200 M€ in new luxury homes; The Residences at Vale do Lobo 40% reserved at groundbreaking. | I21: 2026 | J21: Search result, not opened | K21: Direção de vendas internacionais | L21: Website: valedolobo.com | M21: Area placement (Prime) | N21: =INDEX(Settings!$B$4:$B$15,MATCH(M21,Settings!$A$4:$A$15,0)) | O21: =IF(E21="A",IF(I21>=2022,Settings!$B$18,Settings!$B$19),IF(E21="B",Settings!$B$20,Settings!$B$21))+IF(F21="S",Settings!$B$22,0) | P21: =N21*O21 | Q21: =P21*INDEX(Settings!$B$25:$B$27,MATCH(F21,Settings!$A$25:$A$27,0)) | R21: Not contacted | S21: Approach with brochure (D40) | U21: Partner | V21: not assessed
A22: S194 | B22: Bradesco Europa (Luxembourg) | C22: Private bank (private) | D22: BR, LU | E22: A | F22: L | G22: https://www.suno.com.br/noticias/bradesco-estuda-atender-milionarios-portugal | H22: Wealth Partner tier (D33): Luxembourg unit serves Brazilian clients who moved to Portugal; studying a Portugal office (prompt 15) | I22: 2026 | J22: Search result | K22: Head of international or Portugal desk | L22: LinkedIn (named role), then company email | M22: Wealth Partner | N22: =INDEX(Settings!$B$4:$B$15,MATCH(M22,Settings!$A$4:$A$15,0)) | O22: =IF(E22="A",IF(I22>=2022,Settings!$B$18,Settings!$B$19),IF(E22="B",Settings!$B$20,Settings!$B$21))+IF(F22="S",Settings!$B$22,0) | P22: =N22*O22 | Q22: =P22*INDEX(Settings!$B$25:$B$27,MATCH(F22,Settings!$A$25:$A$27,0)) | R22: To contact | S22: Touch 1 (sponsors/outreach/v3) | T22: 2026-11-09 | U22: Partner | V22: Brazil
A23: S195 | B23: Degroof Petercam Luxembourg | C23: Private bank (private) | D23: LU, FR | E23: A | F23: L | G23: https://www.degroofpetercam.com/en-lu/resident-in-portugal | H23: Wealth Partner tier (D33): Dedicated 'Resident in Portugal' offer and team from Luxembourg (prompt 15) | I23: 2026 | J23: Search result | K23: Head of international or Portugal desk | L23: LinkedIn (named role), then company email | M23: Wealth Partner | N23: =INDEX(Settings!$B$4:$B$15,MATCH(M23,Settings!$A$4:$A$15,0)) | O23: =IF(E23="A",IF(I23>=2022,Settings!$B$18,Settings!$B$19),IF(E23="B",Settings!$B$20,Settings!$B$21))+IF(F23="S",Settings!$B$22,0) | P23: =N23*O23 | Q23: =P23*INDEX(Settings!$B$25:$B$27,MATCH(F23,Settings!$A$25:$A$27,0)) | R23: To contact | S23: Touch 1 (sponsors/outreach/v3) | T23: 2026-11-09 | U23: Partner | V23: Belgium
A24: S196 | B24: Discovery Land Company (Costa Terra Golf & Ocean Club) | C24: Prime developer (private) | D24: US, FR, CH, LU | E24: A | F24: L | G24: https://www.idealista.com/news/etiquetas/comporta | H24: Wealth Partner tier (D33): Costa Terra project in Melides (Grândola) selling plots to international buyers (prompt 15) | I24: 2024 | J24: Search result | K24: Sales or marketing director | L24: LinkedIn (named role), then company email | M24: Wealth Partner | N24: =INDEX(Settings!$B$4:$B$15,MATCH(M24,Settings!$A$4:$A$15,0)) | O24: =IF(E24="A",IF(I24>=2022,Settings!$B$18,Settings!$B$19),IF(E24="B",Settings!$B$20,Settings!$B$21))+IF(F24="S",Settings!$B$22,0) | P24: =N24*O24 | Q24: =P24*INDEX(Settings!$B$25:$B$27,MATCH(F24,Settings!$A$25:$A$27,0)) | R24: To contact | S24: Touch 1 (sponsors/outreach/v3) | T24: 2026-11-09 | U24: Partner | V24: United States
A25: S197 | B25: Edmond de Rothschild | C25: Private bank (private) | D25: CH, LU, FR | E25: A | F25: L | G25: https://www.bloomberglinea.com.br/2025/03/26/de-saida-do-brasil-julius-baer-planeja-abrir-escritorio-em-lisboa-e-mira-estrangeiros/ | H25: Wealth Partner tier (D33): Listed among private banks present in Lisbon serving foreigners (prompt 15) | I25: 2025 | J25: Search result | K25: Head of international or Portugal desk | L25: LinkedIn (named role), then company email | M25: Wealth Partner | N25: =INDEX(Settings!$B$4:$B$15,MATCH(M25,Settings!$A$4:$A$15,0)) | O25: =IF(E25="A",IF(I25>=2022,Settings!$B$18,Settings!$B$19),IF(E25="B",Settings!$B$20,Settings!$B$21))+IF(F25="S",Settings!$B$22,0) | P25: =N25*O25 | Q25: =P25*INDEX(Settings!$B$25:$B$27,MATCH(F25,Settings!$A$25:$A$27,0)) | R25: To contact | S25: Touch 1 (sponsors/outreach/v3) | T25: 2026-11-09 | U25: Partner | V25: Switzerland
A26: S198 | B26: Indosuez Wealth Management | C26: Private bank (private) | D26: LU, FR, CH | E26: A | F26: L | G26: https://www.privatebankerinternational.com/newsletters/indosuez-wealth-management-sets-up-branch-in-portugal | H26: Wealth Partner tier (D33): Lisbon branch opened 2024 for family offices, entrepreneurs and expatriates; Portuguese desk in Luxembourg (prompt 15) | I26: 2024 | J26: Search result | K26: Head of international or Portugal desk | L26: LinkedIn (named role), then company email | M26: Wealth Partner | N26: =INDEX(Settings!$B$4:$B$15,MATCH(M26,Settings!$A$4:$A$15,0)) | O26: =IF(E26="A",IF(I26>=2022,Settings!$B$18,Settings!$B$19),IF(E26="B",Settings!$B$20,Settings!$B$21))+IF(F26="S",Settings!$B$22,0) | P26: =N26*O26 | Q26: =P26*INDEX(Settings!$B$25:$B$27,MATCH(F26,Settings!$A$25:$A$27,0)) | R26: To contact | S26: Touch 1 (sponsors/outreach/v3) | T26: 2026-11-09 | U26: Partner | V26: France (Crédit Agricole)
A27: S199 | B27: Morais Leitão | C27: Law firm, private clients (private) | D27: LU, FR, CH, BR, US, IL | E27: A | F27: L | G27: https://www.internationaltaxreview.com/itrworldtax/firms/morais-leitao-galvao-teles-soares-da-silva-associados-portugal | H27: Wealth Partner tier (D33): Tax practice with private clients among its clients (prompt 15) | I27: 2026 | J27: Search result | K27: Partner, private clients | L27: LinkedIn (named role), then company email | M27: Wealth Partner | N27: =INDEX(Settings!$B$4:$B$15,MATCH(M27,Settings!$A$4:$A$15,0)) | O27: =IF(E27="A",IF(I27>=2022,Settings!$B$18,Settings!$B$19),IF(E27="B",Settings!$B$20,Settings!$B$21))+IF(F27="S",Settings!$B$22,0) | P27: =N27*O27 | Q27: =P27*INDEX(Settings!$B$25:$B$27,MATCH(F27,Settings!$A$25:$A$27,0)) | R27: To contact | S27: Touch 1 (sponsors/outreach/v3) | T27: 2026-11-09 | U27: Partner | V27: Portugal
A28: S200 | B28: Union Bancaire Privée (UBP) | C28: Private bank (private) | D28: CH, BR | E28: A | F28: L | G28: https://www.bloombergquint.com/onweb/rich-brazilians-moving-to-portugal-pull-local-bankers-with-them | H28: Wealth Partner tier (D33): Lisbon office for wealthy clients moving to Portugal; bought Millennium Banque Privée (Geneva) (prompt 15) | I28: 2024 | J28: Search result | K28: Head of international or Portugal desk | L28: LinkedIn (named role), then company email | M28: Wealth Partner | N28: =INDEX(Settings!$B$4:$B$15,MATCH(M28,Settings!$A$4:$A$15,0)) | O28: =IF(E28="A",IF(I28>=2022,Settings!$B$18,Settings!$B$19),IF(E28="B",Settings!$B$20,Settings!$B$21))+IF(F28="S",Settings!$B$22,0) | P28: =N28*O28 | Q28: =P28*INDEX(Settings!$B$25:$B$27,MATCH(F28,Settings!$A$25:$A$27,0)) | R28: To contact | S28: Touch 1 (sponsors/outreach/v3) | T28: 2026-11-09 | U28: Partner | V28: Switzerland
A29: S201 | B29: VdA Vieira de Almeida | C29: Law firm, private clients (private) | D29: LU, FR, CH, BR, US, IL | E29: A | F29: L | G29: https://chambers.com/department/vda-vieira-de-almeida-private-wealth-law-high-net-worth-21:2633:174:1:3970 | H29: Wealth Partner tier (D33): Ranked private wealth practice advising international family offices, private banks and UHNW individuals (prompt 15) | I29: 2026 | J29: Search result | K29: Partner, private clients | L29: LinkedIn (named role), then company email | M29: Wealth Partner | N29: =INDEX(Settings!$B$4:$B$15,MATCH(M29,Settings!$A$4:$A$15,0)) | O29: =IF(E29="A",IF(I29>=2022,Settings!$B$18,Settings!$B$19),IF(E29="B",Settings!$B$20,Settings!$B$21))+IF(F29="S",Settings!$B$22,0) | P29: =N29*O29 | Q29: =P29*INDEX(Settings!$B$25:$B$27,MATCH(F29,Settings!$A$25:$A$27,0)) | R29: To contact | S29: Touch 1 (sponsors/outreach/v3) | T29: 2026-11-09 | U29: Partner | V29: Portugal
A30: S169 | B30: Andersen Portugal | C30: Estruturação | D30: Todos os países · advogados em Portugal | E30: A | F30: L | G30: https://chambers.com/department/andersen-private-wealth-law-high-net-worth-21:2633:174:1:22620317 | H30: Ranked in private wealth law. | I30: 2026 | J30: Search result, not opened | K30: Private client | L30: Website: pt.andersen.com | M30: Journey checkpoint | N30: =INDEX(Settings!$B$4:$B$15,MATCH(M30,Settings!$A$4:$A$15,0)) | O30: =IF(E30="A",IF(I30>=2022,Settings!$B$18,Settings!$B$19),IF(E30="B",Settings!$B$20,Settings!$B$21))+IF(F30="S",Settings!$B$22,0) | P30: =N30*O30 | Q30: =P30*INDEX(Settings!$B$25:$B$27,MATCH(F30,Settings!$A$25:$A$27,0)) | R30: Not contacted | S30: Approach with brochure (D40) | U30: Partner | V30: not assessed
A31: S166 | B31: BTG Pactual | C31: Estruturação (×1.5) | D31: Brasil | E31: A | F31: L | G31: https://www.essential-business.pt/2019/12/08/btg-pactual-enters-portuguese-banking-market/ | H31: Entered Portuguese banking; expanding European real estate. | I31: 2026 | J31: Search result, not opened | K31: Wealth / Europa | L31: Website: btgpactual.com | M31: Journey checkpoint | N31: =INDEX(Settings!$B$4:$B$15,MATCH(M31,Settings!$A$4:$A$15,0)) | O31: =IF(E31="A",IF(I31>=2022,Settings!$B$18,Settings!$B$19),IF(E31="B",Settings!$B$20,Settings!$B$21))+IF(F31="S",Settings!$B$22,0) | P31: =N31*O31 | Q31: =P31*INDEX(Settings!$B$25:$B$27,MATCH(F31,Settings!$A$25:$A$27,0)) | R31: Not contacted | S31: Approach with brochure (D40) | U31: Partner | V31: not assessed
A32: S168 | B32: CMS Portugal | C32: Estruturação | D32: Todos os países · advogados em Portugal | E32: A | F32: L | G32: https://cms.law/en/prt/news-information/cms-portugal-and-nuno-figueiroa-santos-highlighted-in-the-chambers-and-partners-high-net-worth-guide | H32: Highlighted in Chambers High Net Worth. | I32: 2026 | J32: Search result, not opened | K32: Private client | L32: Website: cms.law | M32: Journey checkpoint | N32: =INDEX(Settings!$B$4:$B$15,MATCH(M32,Settings!$A$4:$A$15,0)) | O32: =IF(E32="A",IF(I32>=2022,Settings!$B$18,Settings!$B$19),IF(E32="B",Settings!$B$20,Settings!$B$21))+IF(F32="S",Settings!$B$22,0) | P32: =N32*O32 | Q32: =P32*INDEX(Settings!$B$25:$B$27,MATCH(F32,Settings!$A$25:$A$27,0)) | R32: Not contacted | S32: Approach with brochure (D40) | U32: Partner | V32: not assessed
A33: S173 | B33: Cleerly | C33: Reforma em Portugal | D33: França | E33: A | F33: L | G33: https://cleerly.fr/retraite/portugal | H33: Wealth-management firm publishing guides on retiring to Portugal. | I33: 2026 | J33: Opened | K33: Marketing | L33: Website: cleerly.fr | M33: Journey checkpoint | N33: =INDEX(Settings!$B$4:$B$15,MATCH(M33,Settings!$A$4:$A$15,0)) | O33: =IF(E33="A",IF(I33>=2022,Settings!$B$18,Settings!$B$19),IF(E33="B",Settings!$B$20,Settings!$B$21))+IF(F33="S",Settings!$B$22,0) | P33: =N33*O33 | Q33: =P33*INDEX(Settings!$B$25:$B$27,MATCH(F33,Settings!$A$25:$A$27,0)) | R33: Not contacted | S33: Approach with brochure (D40) | U33: Partner | V33: not assessed
A34: S171 | B34: Compassurance | C34: 2.º pilar ao sair da Suíça | D34: Suíça | E34: A | F34: L | G34: https://compassurance.ch/retirer-2eme-pilier-quitter-suisse/ | H34: Free expert audit of the 2nd pillar before leaving Switzerland: amount, net tax, canton strategy. | I34: 2026 | J34: Opened | K34: Expert team | L34: Website: compassurance.ch | M34: Journey checkpoint | N34: =INDEX(Settings!$B$4:$B$15,MATCH(M34,Settings!$A$4:$A$15,0)) | O34: =IF(E34="A",IF(I34>=2022,Settings!$B$18,Settings!$B$19),IF(E34="B",Settings!$B$20,Settings!$B$21))+IF(F34="S",Settings!$B$22,0) | P34: =N34*O34 | Q34: =P34*INDEX(Settings!$B$25:$B$27,MATCH(F34,Settings!$A$25:$A$27,0)) | R34: Not contacted | S34: Approach with brochure (D40) | U34: Partner | V34: not assessed
A35: S175 | B35: Creative Planning International | C35: Estruturação (×1.5) | D35: EUA | E35: A | F35: L | G35: https://creativeplanning.com/international/insights/financial-planning/9-critical-financial-planning-considerations-for-american-expats-living-in-portugal/ | H35: US expat wealth services covering Portugal (households with US$500k+ in US assets). | I35: 2026 | J35: Opened | K35: International team | L35: Website: creativeplanning.com | M35: Journey checkpoint | N35: =INDEX(Settings!$B$4:$B$15,MATCH(M35,Settings!$A$4:$A$15,0)) | O35: =IF(E35="A",IF(I35>=2022,Settings!$B$18,Settings!$B$19),IF(E35="B",Settings!$B$20,Settings!$B$21))+IF(F35="S",Settings!$B$22,0) | P35: =N35*O35 | Q35: =P35*INDEX(Settings!$B$25:$B$27,MATCH(F35,Settings!$A$25:$A$27,0)) | R35: Not contacted | S35: Approach with brochure (D40) | U35: Partner | V35: not assessed
A36: S167 | B36: Deloitte Legal | Telles | C36: Estruturação | D36: Todos os países · advogados em Portugal | E36: A | F36: L | G36: https://www.deloitte.com/pt/pt/services/legal/blogs/news/deloitte-legal-telles-band-1-private-wealth-law.html | H36: Band 1 in private wealth law. | I36: 2026 | J36: Search result, not opened | K36: Private wealth | L36: Website: deloitte.com/pt | M36: Journey checkpoint | N36: =INDEX(Settings!$B$4:$B$15,MATCH(M36,Settings!$A$4:$A$15,0)) | O36: =IF(E36="A",IF(I36>=2022,Settings!$B$18,Settings!$B$19),IF(E36="B",Settings!$B$20,Settings!$B$21))+IF(F36="S",Settings!$B$22,0) | P36: =N36*O36 | Q36: =P36*INDEX(Settings!$B$25:$B$27,MATCH(F36,Settings!$A$25:$A$27,0)) | R36: Not contacted | S36: Approach with brochure (D40) | U36: Partner | V36: not assessed
A37: S174 | B37: FRESH Legal | C37: Impostos nos EUA e em Portugal | D37: EUA | E37: A | F37: L | G37: https://fresh-legal.com/us | H37: Cross-border US tax planning and filing; Lisbon office and Portuguese legal practice. | I37: 2026 | J37: Opened | K37: Partners | L37: Website: fresh-legal.com | M37: Journey checkpoint | N37: =INDEX(Settings!$B$4:$B$15,MATCH(M37,Settings!$A$4:$A$15,0)) | O37: =IF(E37="A",IF(I37>=2022,Settings!$B$18,Settings!$B$19),IF(E37="B",Settings!$B$20,Settings!$B$21))+IF(F37="S",Settings!$B$22,0) | P37: =N37*O37 | Q37: =P37*INDEX(Settings!$B$25:$B$27,MATCH(F37,Settings!$A$25:$A$27,0)) | R37: Not contacted | S37: Approach with brochure (D40) | U37: Partner | V37: not assessed
A38: S172 | B38: Hagnéré Patrimoine | C38: Estruturação (×1.5) | D38: França | E38: A | F38: L | G38: https://www.hagnere-patrimoine.fr/gestion-de-patrimoine-expatrie-portugal | H38: Wealth adviser for French expatriates in Portugal: Franco-Portuguese tax, works with licensed Portuguese professionals. | I38: 2026 | J38: Opened | K38: Founding partner | L38: Website: hagnere-patrimoine.fr | M38: Journey checkpoint | N38: =INDEX(Settings!$B$4:$B$15,MATCH(M38,Settings!$A$4:$A$15,0)) | O38: =IF(E38="A",IF(I38>=2022,Settings!$B$18,Settings!$B$19),IF(E38="B",Settings!$B$20,Settings!$B$21))+IF(F38="S",Settings!$B$22,0) | P38: =N38*O38 | Q38: =P38*INDEX(Settings!$B$25:$B$27,MATCH(F38,Settings!$A$25:$A$27,0)) | R38: Not contacted | S38: Approach with brochure (D40) | U38: Partner | V38: not assessed
A39: S165 | B39: Julius Baer | C39: Estruturação (×1.5) | D39: Suíça | E39: A | F39: L | G39: https://www.essential-business.pt/2025/03/27/swiss-wealth-management-and-investment-bank-julius-baer-to-open-lisbon-office/ | H39: Opened a Lisbon office in 2025 for Portugal-linked wealth clients. | I39: 2026 | J39: Search result, not opened | K39: Head of Portugal desk | L39: Website: juliusbaer.com | M39: Journey checkpoint | N39: =INDEX(Settings!$B$4:$B$15,MATCH(M39,Settings!$A$4:$A$15,0)) | O39: =IF(E39="A",IF(I39>=2022,Settings!$B$18,Settings!$B$19),IF(E39="B",Settings!$B$20,Settings!$B$21))+IF(F39="S",Settings!$B$22,0) | P39: =N39*O39 | Q39: =P39*INDEX(Settings!$B$25:$B$27,MATCH(F39,Settings!$A$25:$A$27,0)) | R39: Not contacted | S39: Approach with brochure (D40) | U39: Partner | V39: not assessed
A40: S161 | B40: Krest | C40: Developer (Lisboa (Marvila)) | D40: LU, FR, CH, BR, US, IL | E40: A | F40: L | G40: https://www.essential-business.pt/2025/11/21/krest-unveils-formoso-marvila-residential-development-in-lisbon/ | H40: Formoso Marvila residential development unveiled in late 2025. | I40: 2026 | J40: Search result, not opened | K40: Marketing e vendas | L40: Website contact / LinkedIn | M40: Area placement (Strong) | N40: =INDEX(Settings!$B$4:$B$15,MATCH(M40,Settings!$A$4:$A$15,0)) | O40: =IF(E40="A",IF(I40>=2022,Settings!$B$18,Settings!$B$19),IF(E40="B",Settings!$B$20,Settings!$B$21))+IF(F40="S",Settings!$B$22,0) | P40: =N40*O40 | Q40: =P40*INDEX(Settings!$B$25:$B$27,MATCH(F40,Settings!$A$25:$A$27,0)) | R40: Not contacted | S40: Approach with brochure (D40) | U40: Partner | V40: not assessed
...

Sheet Later (tier C)
A1: ID | B1: Company | C1: Sector | D1: Editions | E1: Tier | F1: Size | G1: Evidence URL | H1: Evidence | I1: Evidence year | J1: Evidence check | K1: Who to reach | L1: Channel | M1: Offer | N1: Deal value year 1 (€) | O1: Close probability | P1: Expected value (€) | Q1: Priority score | R1: Status | S1: Next action | T1: Next action date | U1: Owner | V1: Capital origin
A2: S071 | B2: AGS Four Winds | C2: Moving | D2: LU, FR, CH, BR | E2: C | F2: L | H2: Large or generic; no proof of spend on our audience | K2: Owner or marketing lead | L2: LinkedIn (named role); general partnerships email as backup | M2: Silver | N2: =INDEX(Settings!$B$4:$B$15,MATCH(M2,Settings!$A$4:$A$15,0)) | O2: =IF(E2="A",IF(I2>=2022,Settings!$B$18,Settings!$B$19),IF(E2="B",Settings!$B$20,Settings!$B$21))+IF(F2="S",Settings!$B$22,0) | P2: =N2*O2 | Q2: =P2*INDEX(Settings!$B$25:$B$27,MATCH(F2,Settings!$A$25:$A$27,0)) | R2: Parked | S2: Revisit when 1,000 subscribers or a warm intro exists | T2: 2026-12-01 | U2: CEO | V2: not assessed
A3: S150 | B3: ARAG | C3: Insurance | D3: LU, FR, CH, BR, US, IL | E3: C | F3: L | G3: https://www.doutorfinancas.pt/seguro-vida-geral/ | H3: Insurer listed as a partner by Doutor Finanças' insurance intermediary (Doutor Finanças Protege) (prompt 13); no proof of spend on our audience | I3: 2026 | J3: Fetched | K3: Marketing lead, intermediary / partnerships | L3: LinkedIn (named role); general partnerships email as backup | M3: Silver | N3: =INDEX(Settings!$B$4:$B$15,MATCH(M3,Settings!$A$4:$A$15,0)) | O3: =IF(E3="A",IF(I3>=2022,Settings!$B$18,Settings!$B$19),IF(E3="B",Settings!$B$20,Settings!$B$21))+IF(F3="S",Settings!$B$22,0) | P3: =N3*O3 | Q3: =P3*INDEX(Settings!$B$25:$B$27,MATCH(F3,Settings!$A$25:$A$27,0)) | R3: Parked | S3: Revisit when 1,000 subscribers or a warm intro exists | T3: 2026-12-01 | U3: CEO | V3: not assessed
A4: S072 | B4: Allianz Portugal | C4: Insurance | D4: LU, FR, CH, BR | E4: C | F4: L | H4: Large or generic; no proof of spend on our audience | K4: Marketing lead, retail | L4: LinkedIn (named role); general partnerships email as backup | M4: Silver | N4: =INDEX(Settings!$B$4:$B$15,MATCH(M4,Settings!$A$4:$A$15,0)) | O4: =IF(E4="A",IF(I4>=2022,Settings!$B$18,Settings!$B$19),IF(E4="B",Settings!$B$20,Settings!$B$21))+IF(F4="S",Settings!$B$22,0) | P4: =N4*O4 | Q4: =P4*INDEX(Settings!$B$25:$B$27,MATCH(F4,Settings!$A$25:$A$27,0)) | R4: Parked | S4: Revisit when 1,000 subscribers or a warm intro exists | T4: 2026-12-01 | U4: CEO | V4: not assessed
A5: S073 | B5: Allied Pickfords | C5: Moving | D5: LU, FR, CH, BR | E5: C | F5: L | H5: Large or generic; no proof of spend on our audience | K5: Owner or marketing lead | L5: LinkedIn (named role); general partnerships email as backup | M5: Silver | N5: =INDEX(Settings!$B$4:$B$15,MATCH(M5,Settings!$A$4:$A$15,0)) | O5: =IF(E5="A",IF(I5>=2022,Settings!$B$18,Settings!$B$19),IF(E5="B",Settings!$B$20,Settings!$B$21))+IF(F5="S",Settings!$B$22,0) | P5: =N5*O5 | Q5: =P5*INDEX(Settings!$B$25:$B$27,MATCH(F5,Settings!$A$25:$A$27,0)) | R5: Parked | S5: Revisit when 1,000 subscribers or a warm intro exists | T5: 2026-12-01 | U5: CEO | V5: not assessed
A6: S074 | B6: Altido | C6: Rental management | D6: LU, FR, CH, BR | E6: C | F6: L | H6: Large or generic; no proof of spend on our audience | K6: Owner or marketing lead | L6: LinkedIn (named role); general partnerships email as backup | M6: Silver | N6: =INDEX(Settings!$B$4:$B$15,MATCH(M6,Settings!$A$4:$A$15,0)) | O6: =IF(E6="A",IF(I6>=2022,Settings!$B$18,Settings!$B$19),IF(E6="B",Settings!$B$20,Settings!$B$21))+IF(F6="S",Settings!$B$22,0) | P6: =N6*O6 | Q6: =P6*INDEX(Settings!$B$25:$B$27,MATCH(F6,Settings!$A$25:$A$27,0)) | R6: Parked | S6: Revisit when 1,000 subscribers or a warm intro exists | T6: 2026-12-01 | U6: CEO | V6: not assessed
A7: S144 | B7: April Portugal | C7: Insurance | D7: LU, FR, CH, BR, US, IL | E7: C | F7: L | G7: https://www.doutorfinancas.pt/seguro-vida-geral/ | H7: Insurer listed as a partner by Doutor Finanças' insurance intermediary (Doutor Finanças Protege) (prompt 13); no proof of spend on our audience | I7: 2026 | J7: Fetched | K7: Marketing lead, intermediary / partnerships | L7: LinkedIn (named role); general partnerships email as backup | M7: Silver | N7: =INDEX(Settings!$B$4:$B$15,MATCH(M7,Settings!$A$4:$A$15,0)) | O7: =IF(E7="A",IF(I7>=2022,Settings!$B$18,Settings!$B$19),IF(E7="B",Settings!$B$20,Settings!$B$21))+IF(F7="S",Settings!$B$22,0) | P7: =N7*O7 | Q7: =P7*INDEX(Settings!$B$25:$B$27,MATCH(F7,Settings!$A$25:$A$27,0)) | R7: Parked | S7: Revisit when 1,000 subscribers or a warm intro exists | T7: 2026-12-01 | U7: CEO | V7: not assessed
A8: S146 | B8: Asisa | C8: Insurance | D8: LU, FR, CH, BR, US, IL | E8: C | F8: L | G8: https://www.doutorfinancas.pt/seguro-vida-geral/ | H8: Insurer listed as a partner by Doutor Finanças' insurance intermediary (Doutor Finanças Protege) (prompt 13); no proof of spend on our audience | I8: 2026 | J8: Fetched | K8: Marketing lead, intermediary / partnerships | L8: LinkedIn (named role); general partnerships email as backup | M8: Silver | N8: =INDEX(Settings!$B$4:$B$15,MATCH(M8,Settings!$A$4:$A$15,0)) | O8: =IF(E8="A",IF(I8>=2022,Settings!$B$18,Settings!$B$19),IF(E8="B",Settings!$B$20,Settings!$B$21))+IF(F8="S",Settings!$B$22,0) | P8: =N8*O8 | Q8: =P8*INDEX(Settings!$B$25:$B$27,MATCH(F8,Settings!$A$25:$A$27,0)) | R8: Parked | S8: Revisit when 1,000 subscribers or a warm intro exists | T8: 2026-12-01 | U8: CEO | V8: not assessed
A9: S076 | B9: Atlantic Bridge | C9: Relocation (Brazil) | D9: BR | E9: C | F9: L | H9: Large or generic; no proof of spend on our audience | K9: Owner or marketing lead | L9: LinkedIn (named role); general partnerships email as backup | M9: Silver | N9: =INDEX(Settings!$B$4:$B$15,MATCH(M9,Settings!$A$4:$A$15,0)) | O9: =IF(E9="A",IF(I9>=2022,Settings!$B$18,Settings!$B$19),IF(E9="B",Settings!$B$20,Settings!$B$21))+IF(F9="S",Settings!$B$22,0) | P9: =N9*O9 | Q9: =P9*INDEX(Settings!$B$25:$B$27,MATCH(F9,Settings!$A$25:$A$27,0)) | R9: Parked | S9: Revisit when 1,000 subscribers or a warm intro exists | T9: 2026-12-01 | U9: CEO | V9: not assessed
A10: S078 | B10: BGL BNP Paribas | C10: Bank (Luxembourg) | D10: LU | E10: C | F10: L | H10: Large or generic; no proof of spend on our audience | K10: Marketing lead, non-resident / emigrant segment | L10: LinkedIn (named role); general partnerships email as backup | M10: Gold | N10: =INDEX(Settings!$B$4:$B$15,MATCH(M10,Settings!$A$4:$A$15,0)) | O10: =IF(E10="A",IF(I10>=2022,Settings!$B$18,Settings!$B$19),IF(E10="B",Settings!$B$20,Settings!$B$21))+IF(F10="S",Settings!$B$22,0) | P10: =N10*O10 | Q10: =P10*INDEX(Settings!$B$25:$B$27,MATCH(F10,Settings!$A$25:$A$27,0)) | R10: Parked | S10: Revisit when 1,000 subscribers or a warm intro exists | T10: 2026-12-01 | U10: CEO | V10: not assessed
A11: S079 | B11: Banco Inter | C11: Bank (Brazil) | D11: BR | E11: C | F11: L | H11: Large or generic; no proof of spend on our audience | K11: Marketing lead, non-resident / emigrant segment | L11: LinkedIn (named role); general partnerships email as backup | M11: Gold | N11: =INDEX(Settings!$B$4:$B$15,MATCH(M11,Settings!$A$4:$A$15,0)) | O11: =IF(E11="A",IF(I11>=2022,Settings!$B$18,Settings!$B$19),IF(E11="B",Settings!$B$20,Settings!$B$21))+IF(F11="S",Settings!$B$22,0) | P11: =N11*O11 | Q11: =P11*INDEX(Settings!$B$25:$B$27,MATCH(F11,Settings!$A$25:$A$27,0)) | R11: Parked | S11: Revisit when 1,000 subscribers or a warm intro exists | T11: 2026-12-01 | U11: CEO | V11: not assessed
A12: S080 | B12: Banco do Brasil (Portugal) | C12: Bank | D12: LU, FR, CH, BR | E12: C | F12: L | H12: Large or generic; no proof of spend on our audience | K12: Marketing lead, non-resident / emigrant segment | L12: LinkedIn (named role); general partnerships email as backup | M12: Gold | N12: =INDEX(Settings!$B$4:$B$15,MATCH(M12,Settings!$A$4:$A$15,0)) | O12: =IF(E12="A",IF(I12>=2022,Settings!$B$18,Settings!$B$19),IF(E12="B",Settings!$B$20,Settings!$B$21))+IF(F12="S",Settings!$B$22,0) | P12: =N12*O12 | Q12: =P12*INDEX(Settings!$B$25:$B$27,MATCH(F12,Settings!$A$25:$A$27,0)) | R12: Parked | S12: Revisit when 1,000 subscribers or a warm intro exists | T12: 2026-12-01 | U12: CEO | V12: not assessed
A13: S081 | B13: Bankinter Portugal | C13: Bank | D13: LU, FR, CH, BR | E13: C | F13: L | H13: Large or generic; no proof of spend on our audience | K13: Marketing lead, non-resident / emigrant segment | L13: LinkedIn (named role); general partnerships email as backup | M13: Gold | N13: =INDEX(Settings!$B$4:$B$15,MATCH(M13,Settings!$A$4:$A$15,0)) | O13: =IF(E13="A",IF(I13>=2022,Settings!$B$18,Settings!$B$19),IF(E13="B",Settings!$B$20,Settings!$B$21))+IF(F13="S",Settings!$B$22,0) | P13: =N13*O13 | Q13: =P13*INDEX(Settings!$B$25:$B$27,MATCH(F13,Settings!$A$25:$A$27,0)) | R13: Parked | S13: Revisit when 1,000 subscribers or a warm intro exists | T13: 2026-12-01 | U13: CEO | V13: not assessed
A14: S082 | B14: Banque Raiffeisen | C14: Bank (Luxembourg) | D14: LU | E14: C | F14: L | H14: Large or generic; no proof of spend on our audience | K14: Marketing lead, non-resident / emigrant segment | L14: LinkedIn (named role); general partnerships email as backup | M14: Gold | N14: =INDEX(Settings!$B$4:$B$15,MATCH(M14,Settings!$A$4:$A$15,0)) | O14: =IF(E14="A",IF(I14>=2022,Settings!$B$18,Settings!$B$19),IF(E14="B",Settings!$B$20,Settings!$B$21))+IF(F14="S",Settings!$B$22,0) | P14: =N14*O14 | Q14: =P14*INDEX(Settings!$B$25:$B$27,MATCH(F14,Settings!$A$25:$A$27,0)) | R14: Parked | S14: Revisit when 1,000 subscribers or a warm intro exists | T14: 2026-12-01 | U14: CEO | V14: not assessed
A15: S147 | B15: Bupa (Portugal) | C15: Insurance | D15: LU, FR, CH, BR, US, IL | E15: C | F15: L | G15: https://www.doutorfinancas.pt/seguro-vida-geral/ | H15: Insurer listed as a partner by Doutor Finanças' insurance intermediary (Doutor Finanças Protege) (prompt 13); no proof of spend on our audience | I15: 2026 | J15: Fetched | K15: Marketing lead, intermediary / partnerships | L15: LinkedIn (named role); general partnerships email as backup | M15: Silver | N15: =INDEX(Settings!$B$4:$B$15,MATCH(M15,Settings!$A$4:$A$15,0)) | O15: =IF(E15="A",IF(I15>=2022,Settings!$B$18,Settings!$B$19),IF(E15="B",Settings!$B$20,Settings!$B$21))+IF(F15="S",Settings!$B$22,0) | P15: =N15*O15 | Q15: =P15*INDEX(Settings!$B$25:$B$27,MATCH(F15,Settings!$A$25:$A$27,0)) | R15: Parked | S15: Revisit when 1,000 subscribers or a warm intro exists | T15: 2026-12-01 | U15: CEO | V15: not assessed
A16: S083 | B16: C6 Bank | C16: Bank (Brazil) | D16: BR | E16: C | F16: L | H16: Large or generic; no proof of spend on our audience | K16: Marketing lead, non-resident / emigrant segment | L16: LinkedIn (named role); general partnerships email as backup | M16: Gold | N16: =INDEX(Settings!$B$4:$B$15,MATCH(M16,Settings!$A$4:$A$15,0)) | O16: =IF(E16="A",IF(I16>=2022,Settings!$B$18,Settings!$B$19),IF(E16="B",Settings!$B$20,Settings!$B$21))+IF(F16="S",Settings!$B$22,0) | P16: =N16*O16 | Q16: =P16*INDEX(Settings!$B$25:$B$27,MATCH(F16,Settings!$A$25:$A$27,0)) | R16: Parked | S16: Revisit when 1,000 subscribers or a warm intro exists | T16: 2026-12-01 | U16: CEO | V16: not assessed
A17: S084 | B17: Caiado Guerreiro | C17: Law firm | D17: LU, FR, CH, BR | E17: C | F17: L | H17: Large or generic; no proof of spend on our audience | K17: Managing partner or business development | L17: LinkedIn (named role); general partnerships email as backup | M17: Silver | N17: =INDEX(Settings!$B$4:$B$15,MATCH(M17,Settings!$A$4:$A$15,0)) | O17: =IF(E17="A",IF(I17>=2022,Settings!$B$18,Settings!$B$19),IF(E17="B",Settings!$B$20,Settings!$B$21))+IF(F17="S",Settings!$B$22,0) | P17: =N17*O17 | Q17: =P17*INDEX(Settings!$B$25:$B$27,MATCH(F17,Settings!$A$25:$A$27,0)) | R17: Parked | S17: Revisit when 1,000 subscribers or a warm intro exists | T17: 2026-12-01 | U17: CEO | V17: not assessed
A18: S141 | B18: Caravela Seguros | C18: Insurance | D18: LU, FR, CH, BR, US, IL | E18: C | F18: L | G18: https://www.doutorfinancas.pt/seguro-vida-geral/ | H18: Insurer listed as a partner by Doutor Finanças' insurance intermediary (Doutor Finanças Protege) (prompt 13); no proof of spend on our audience | I18: 2026 | J18: Fetched | K18: Marketing lead, intermediary / partnerships | L18: LinkedIn (named role); general partnerships email as backup | M18: Silver | N18: =INDEX(Settings!$B$4:$B$15,MATCH(M18,Settings!$A$4:$A$15,0)) | O18: =IF(E18="A",IF(I18>=2022,Settings!$B$18,Settings!$B$19),IF(E18="B",Settings!$B$20,Settings!$B$21))+IF(F18="S",Settings!$B$22,0) | P18: =N18*O18 | Q18: =P18*INDEX(Settings!$B$25:$B$27,MATCH(F18,Settings!$A$25:$A$27,0)) | R18: Parked | S18: Revisit when 1,000 subscribers or a warm intro exists | T18: 2026-12-01 | U18: CEO | V18: not assessed
A19: S085 | B19: Cidadania4u | C19: Citizenship services | D19: LU, FR, CH, BR | E19: C | F19: L | H19: Large or generic; no proof of spend on our audience | K19: Owner or marketing lead | L19: LinkedIn (named role); general partnerships email as backup | M19: Silver | N19: =INDEX(Settings!$B$4:$B$15,MATCH(M19,Settings!$A$4:$A$15,0)) | O19: =IF(E19="A",IF(I19>=2022,Settings!$B$18,Settings!$B$19),IF(E19="B",Settings!$B$20,Settings!$B$21))+IF(F19="S",Settings!$B$22,0) | P19: =N19*O19 | Q19: =P19*INDEX(Settings!$B$25:$B$27,MATCH(F19,Settings!$A$25:$A$27,0)) | R19: Parked | S19: Revisit when 1,000 subscribers or a warm intro exists | T19: 2026-12-01 | U19: CEO | V19: not assessed
A20: S087 | B20: Decisões e Soluções | C20: Credit / real estate network | D20: LU, FR, CH, BR | E20: C | F20: L | H20: Large or generic; no proof of spend on our audience | K20: Partnerships or marketing lead | L20: LinkedIn (named role); general partnerships email as backup | M20: Silver | N20: =INDEX(Settings!$B$4:$B$15,MATCH(M20,Settings!$A$4:$A$15,0)) | O20: =IF(E20="A",IF(I20>=2022,Settings!$B$18,Settings!$B$19),IF(E20="B",Settings!$B$20,Settings!$B$21))+IF(F20="S",Settings!$B$22,0) | P20: =N20*O20 | Q20: =P20*INDEX(Settings!$B$25:$B$27,MATCH(F20,Settings!$A$25:$A$27,0)) | R20: Parked | S20: Revisit when 1,000 subscribers or a warm intro exists | T20: 2026-12-01 | U20: CEO | V20: not assessed
A21: S088 | B21: EDP Comercial | C21: Energy / solar | D21: LU, FR, CH, BR | E21: C | F21: L | H21: Large or generic; no proof of spend on our audience | K21: Owner or marketing lead | L21: LinkedIn (named role); general partnerships email as backup | M21: Silver | N21: =INDEX(Settings!$B$4:$B$15,MATCH(M21,Settings!$A$4:$A$15,0)) | O21: =IF(E21="A",IF(I21>=2022,Settings!$B$18,Settings!$B$19),IF(E21="B",Settings!$B$20,Settings!$B$21))+IF(F21="S",Settings!$B$22,0) | P21: =N21*O21 | Q21: =P21*INDEX(Settings!$B$25:$B$27,MATCH(F21,Settings!$A$25:$A$27,0)) | R21: Parked | S21: Revisit when 1,000 subscribers or a warm intro exists | T21: 2026-12-01 | U21: CEO | V21: not assessed
A22: S089 | B22: Empruntis | C22: Credit broker (France) | D22: FR | E22: C | F22: L | H22: Large or generic; no proof of spend on our audience | K22: Partnerships or marketing lead | L22: LinkedIn (named role); general partnerships email as backup | M22: Silver | N22: =INDEX(Settings!$B$4:$B$15,MATCH(M22,Settings!$A$4:$A$15,0)) | O22: =IF(E22="A",IF(I22>=2022,Settings!$B$18,Settings!$B$19),IF(E22="B",Settings!$B$20,Settings!$B$21))+IF(F22="S",Settings!$B$22,0) | P22: =N22*O22 | Q22: =P22*INDEX(Settings!$B$25:$B$27,MATCH(F22,Settings!$A$25:$A$27,0)) | R22: Parked | S22: Revisit when 1,000 subscribers or a warm intro exists | T22: 2026-12-01 | U22: CEO | V22: not assessed
A23: S145 | B23: Europ Assistance | C23: Insurance | D23: LU, FR, CH, BR, US, IL | E23: C | F23: L | G23: https://www.doutorfinancas.pt/seguro-vida-geral/ | H23: Insurer listed as a partner by Doutor Finanças' insurance intermediary (Doutor Finanças Protege) (prompt 13); no proof of spend on our audience | I23: 2026 | J23: Fetched | K23: Marketing lead, intermediary / partnerships | L23: LinkedIn (named role); general partnerships email as backup | M23: Silver | N23: =INDEX(Settings!$B$4:$B$15,MATCH(M23,Settings!$A$4:$A$15,0)) | O23: =IF(E23="A",IF(I23>=2022,Settings!$B$18,Settings!$B$19),IF(E23="B",Settings!$B$20,Settings!$B$21))+IF(F23="S",Settings!$B$22,0) | P23: =N23*O23 | Q23: =P23*INDEX(Settings!$B$25:$B$27,MATCH(F23,Settings!$A$25:$A$27,0)) | R23: Parked | S23: Revisit when 1,000 subscribers or a warm intro exists | T23: 2026-12-01 | U23: CEO | V23: not assessed
A24: S090 | B24: Feels Like Home | C24: Rental management | D24: LU, FR, CH, BR | E24: C | F24: L | H24: Large or generic; no proof of spend on our audience | K24: Owner or marketing lead | L24: LinkedIn (named role); general partnerships email as backup | M24: Silver | N24: =INDEX(Settings!$B$4:$B$15,MATCH(M24,Settings!$A$4:$A$15,0)) | O24: =IF(E24="A",IF(I24>=2022,Settings!$B$18,Settings!$B$19),IF(E24="B",Settings!$B$20,Settings!$B$21))+IF(F24="S",Settings!$B$22,0) | P24: =N24*O24 | Q24: =P24*INDEX(Settings!$B$25:$B$27,MATCH(F24,Settings!$A$25:$A$27,0)) | R24: Parked | S24: Revisit when 1,000 subscribers or a warm intro exists | T24: 2026-12-01 | U24: CEO | V24: not assessed
A25: S091 | B25: Fixando | C25: Services marketplace | D25: LU, FR, CH, BR | E25: C | F25: L | H25: Large or generic; no proof of spend on our audience | K25: Owner or marketing lead | L25: LinkedIn (named role); general partnerships email as backup | M25: Silver | N25: =INDEX(Settings!$B$4:$B$15,MATCH(M25,Settings!$A$4:$A$15,0)) | O25: =IF(E25="A",IF(I25>=2022,Settings!$B$18,Settings!$B$19),IF(E25="B",Settings!$B$20,Settings!$B$21))+IF(F25="S",Settings!$B$22,0) | P25: =N25*O25 | Q25: =P25*INDEX(Settings!$B$25:$B$27,MATCH(F25,Settings!$A$25:$A$27,0)) | R25: Parked | S25: Revisit when 1,000 subscribers or a warm intro exists | T25: 2026-12-01 | U25: CEO | V25: not assessed
A26: S154 | B26: Fortera | C26: Developer | D26: IL, US | E26: C | F26: L | G26: https://www.essential-business.pt/?p=16891 | H26: Israeli developer; 500 M€ plan for about 1,000 homes in Greater Porto (Mar 2022), Skyline tower in Gaia. No evidence of marketing to foreign buyers, and it advertises an average 24% yield to investors, which our editorial policy does not let us repeat | I26: 2022 | J26: Fetched | K26: Sales or marketing director | L26: LinkedIn (named role); general partnerships email as backup | M26: Campaign | N26: =INDEX(Settings!$B$4:$B$15,MATCH(M26,Settings!$A$4:$A$15,0)) | O26: =IF(E26="A",IF(I26>=2022,Settings!$B$18,Settings!$B$19),IF(E26="B",Settings!$B$20,Settings!$B$21))+IF(F26="S",Settings!$B$22,0) | P26: =N26*O26 | Q26: =P26*INDEX(Settings!$B$25:$B$27,MATCH(F26,Settings!$A$25:$A$27,0)) | R26: Parked | S26: Revisit when 1,000 subscribers or a warm intro exists | T26: 2026-12-01 | U26: CEO | V26: Israel
A27: S092 | B27: Foyer | C27: Insurance (Luxembourg) | D27: LU | E27: C | F27: L | H27: Large or generic; no proof of spend on our audience | K27: Marketing lead, retail | L27: LinkedIn (named role); general partnerships email as backup | M27: Silver | N27: =INDEX(Settings!$B$4:$B$15,MATCH(M27,Settings!$A$4:$A$15,0)) | O27: =IF(E27="A",IF(I27>=2022,Settings!$B$18,Settings!$B$19),IF(E27="B",Settings!$B$20,Settings!$B$21))+IF(F27="S",Settings!$B$22,0) | P27: =N27*O27 | Q27: =P27*INDEX(Settings!$B$25:$B$27,MATCH(F27,Settings!$A$25:$A$27,0)) | R27: Parked | S27: Revisit when 1,000 subscribers or a warm intro exists | T27: 2026-12-01 | U27: CEO | V27: not assessed
A28: S093 | B28: Galp Solar | C28: Solar | D28: LU, FR, CH, BR | E28: C | F28: L | H28: Large or generic; no proof of spend on our audience | K28: Owner or marketing lead | L28: LinkedIn (named role); general partnerships email as backup | M28: Silver | N28: =INDEX(Settings!$B$4:$B$15,MATCH(M28,Settings!$A$4:$A$15,0)) | O28: =IF(E28="A",IF(I28>=2022,Settings!$B$18,Settings!$B$19),IF(E28="B",Settings!$B$20,Settings!$B$21))+IF(F28="S",Settings!$B$22,0) | P28: =N28*O28 | Q28: =P28*INDEX(Settings!$B$25:$B$27,MATCH(F28,Settings!$A$25:$A$27,0)) | R28: Parked | S28: Revisit when 1,000 subscribers or a warm intro exists | T28: 2026-12-01 | U28: CEO | V28: not assessed
A29: S094 | B29: Generali Tranquilidade | C29: Insurance | D29: LU, FR, CH, BR | E29: C | F29: L | H29: Large or generic; no proof of spend on our audience | K29: Marketing lead, retail | L29: LinkedIn (named role); general partnerships email as backup | M29: Silver | N29: =INDEX(Settings!$B$4:$B$15,MATCH(M29,Settings!$A$4:$A$15,0)) | O29: =IF(E29="A",IF(I29>=2022,Settings!$B$18,Settings!$B$19),IF(E29="B",Settings!$B$20,Settings!$B$21))+IF(F29="S",Settings!$B$22,0) | P29: =N29*O29 | Q29: =P29*INDEX(Settings!$B$25:$B$27,MATCH(F29,Settings!$A$25:$A$27,0)) | R29: Parked | S29: Revisit when 1,000 subscribers or a warm intro exists | T29: 2026-12-01 | U29: CEO | V29: not assessed
A30: S095 | B30: Global Citizen Solutions | C30: Residency advisory | D30: LU, FR, CH, BR | E30: C | F30: L | H30: Large or generic; no proof of spend on our audience | K30: Managing partner or business development | L30: LinkedIn (named role); general partnerships email as backup | M30: Silver | N30: =INDEX(Settings!$B$4:$B$15,MATCH(M30,Settings!$A$4:$A$15,0)) | O30: =IF(E30="A",IF(I30>=2022,Settings!$B$18,Settings!$B$19),IF(E30="B",Settings!$B$20,Settings!$B$21))+IF(F30="S",Settings!$B$22,0) | P30: =N30*O30 | Q30: =P30*INDEX(Settings!$B$25:$B$27,MATCH(F30,Settings!$A$25:$A$27,0)) | R30: Parked | S30: Revisit when 1,000 subscribers or a warm intro exists | T30: 2026-12-01 | U30: CEO | V30: not assessed
A31: S142 | B31: Habit Seguros | C31: Insurance | D31: LU, FR, CH, BR, US, IL | E31: C | F31: L | G31: https://www.doutorfinancas.pt/seguro-vida-geral/ | H31: Insurer listed as a partner by Doutor Finanças' insurance intermediary (Doutor Finanças Protege) (prompt 13); no proof of spend on our audience | I31: 2026 | J31: Fetched | K31: Marketing lead, intermediary / partnerships | L31: LinkedIn (named role); general partnerships email as backup | M31: Silver | N31: =INDEX(Settings!$B$4:$B$15,MATCH(M31,Settings!$A$4:$A$15,0)) | O31: =IF(E31="A",IF(I31>=2022,Settings!$B$18,Settings!$B$19),IF(E31="B",Settings!$B$20,Settings!$B$21))+IF(F31="S",Settings!$B$22,0) | P31: =N31*O31 | Q31: =P31*INDEX(Settings!$B$25:$B$27,MATCH(F31,Settings!$A$25:$A$27,0)) | R31: Parked | S31: Revisit when 1,000 subscribers or a warm intro exists | T31: 2026-12-01 | U31: CEO | V31: not assessed
A32: S096 | B32: IKEA Portugal | C32: Home furnishing | D32: LU, FR, CH, BR | E32: C | F32: L | H32: Large or generic; no proof of spend on our audience | K32: Owner or marketing lead | L32: LinkedIn (named role); general partnerships email as backup | M32: Silver | N32: =INDEX(Settings!$B$4:$B$15,MATCH(M32,Settings!$A$4:$A$15,0)) | O32: =IF(E32="A",IF(I32>=2022,Settings!$B$18,Settings!$B$19),IF(E32="B",Settings!$B$20,Settings!$B$21))+IF(F32="S",Settings!$B$22,0) | P32: =N32*O32 | Q32: =P32*INDEX(Settings!$B$25:$B$27,MATCH(F32,Settings!$A$25:$A$27,0)) | R32: Parked | S32: Revisit when 1,000 subscribers or a warm intro exists | T32: 2026-12-01 | U32: CEO | V32: not assessed
A33: S097 | B33: ING Luxembourg | C33: Bank (Luxembourg) | D33: LU | E33: C | F33: L | H33: Large or generic; no proof of spend on our audience | K33: Marketing lead, non-resident / emigrant segment | L33: LinkedIn (named role); general partnerships email as backup | M33: Gold | N33: =INDEX(Settings!$B$4:$B$15,MATCH(M33,Settings!$A$4:$A$15,0)) | O33: =IF(E33="A",IF(I33>=2022,Settings!$B$18,Settings!$B$19),IF(E33="B",Settings!$B$20,Settings!$B$21))+IF(F33="S",Settings!$B$22,0) | P33: =N33*O33 | Q33: =P33*INDEX(Settings!$B$25:$B$27,MATCH(F33,Settings!$A$25:$A$27,0)) | R33: Parked | S33: Revisit when 1,000 subscribers or a warm intro exists | T33: 2026-12-01 | U33: CEO | V33: not assessed
